Workbook

Sheet Calcul Complet 1990-1996
A1: Année/Employeur | B1: Détail | C1: FRF | D1: EUR (avant cap) | E1: Plafond EUR | F1: Dépassement | G1: EUR (après cap) | H1: Coef | I1: EUR Actualisé | K1: 1 euro
A2: 1990 | K2: 6.55957
B3: GERME | C3: 33120 | D3: 5049.11 | E3: 33741.02 | F3: NON | G3: 5049.11 | H3: 1.689 | I3: 8527.95
B4: Rappels 1990 | C4: 19791.71 | D4: 3017.23 | E4: 33741.02 | F4: NON | G4: 3017.23 | H4: 1.689 | I4: 5096.1 | K4: =(C3+C4)/K2 -> 8066.3382
A5: TOTAL 1990 | H5: =I3+I4 -> 13624.05 | L5: 19976.92
L6: 21001.38
A7: 1991 | L7: 21970.95
B8: GERME | C8: 112024 | D8: 17077.95 | E8: 34925.29 | F8: NON | G8: 17077.95 | H8: 1.663 | I8: 28400.63 | L8: 22839.91
B9: Rappels 1991 | C9: 68913 | D9: 10505.72 | E9: 34925.29 | F9: NON | G9: 10505.72 | H9: 1.663 | I9: 17471.01 | L9: 23342.99
A10: TOTAL 1991 | H10: 45871.64 | L10: 23772.9
L11: 24577.83
A12: 1992 | K12: =(C13+C17)/K2 -> 25511.064
B13: GERME | C13: 103829 | D13: 15828.63 | E13: 35351.26 | F13: NON | G13: 15828.63 | H13: 1.609 | I13: 25468.26
B14: CENTRE VALORISATION | C14: 19793 | D14: 3017.42 | E14: 35351.26 | F14: NON | G14: 3017.42 | H14: 1.609 | I14: 4855.03
B15: OBJECTIF FORMATION | C15: 16485 | D15: 2513.12 | E15: 35351.26 | F15: NON | G15: 2513.12 | H15: 1.609 | I15: 4043.61
B16: GROUP EUROP | C16: 5400 | D16: 823.22 | E16: 35351.26 | F16: NON | G16: 823.22 | H16: 1.609 | I16: 1324.57
B17: Rappels 1992 | C17: 63512.61 | D17: 9682.43 | E17: 35351.26 | F17: NON | G17: 9682.43 | H17: 1.609 | I17: 15579.04
A18: TOTAL 1992 | H18: 51270.518
A19: 1993
B20: GERME | C20: 99462 | D20: 15162.88 | E20: 36749.42 | F20: NON | G20: 15162.88 | H20: 1.609 | I20: 24397.08 | K20: =(C20+C23)/K2 -> 26168.333
B21: OBJECTIF FORMATION | C21: 78195 | D21: 11920.75 | E21: 36749.42 | F21: NON | G21: 11920.75 | H21: 1.609 | I21: 19180.49
B22: GROUP EUROP | C22: 9000 | D22: 1372.04 | E22: 36749.42 | F22: NON | G22: 1372.04 | H22: 1.609 | I22: 2207.61
B23: Rappels GERME 1993 | C23: 72191.01 | D23: 11005.45 | E23: 36749.42 | F23: NON | G23: 11005.45 | H23: 1.609 | I23: 17707.77
A24: TOTAL 1993 | H24: 63492.95
A26: 1994
B27: GERME | C27: 55218.32 | D27: 8417.98 | E27: 36905.27 | F27: NON | G27: 8417.98 | H27: 1.581 | I27: 13308.82
B28: Rappels 1994 | C28: 84581.68 | D28: 12894.39 | E28: 36905.27 | F28: NON | G28: 12894.39 | H28: 1.581 | I28: 20386.04 | K28: =(C27+C28)/K2 -> 21312.373
B29: OBJECTIF FORMATION | C29: 46098 | D29: 7027.59 | E29: 36905.27 | F29: NON | G29: 7027.59 | H29: 1.581 | I29: 11110.63
B30: INSTITUT SUP (3 entrées) | C30: 95040 | D30: 14488.75 | E30: 36905.27 | F30: NON | G30: 14488.75 | H30: 1.581 | I30: 22906.72
A31: TOTAL 1994 | H31: 67712.209
A33: 1995 | K33: 139354.43
B34: GERME | C34: 70313 | D34: =C34/K2 -> 10719.148 | E34: 37157.04 | F34: OUI | G34: =E34 -> 37157.04 | H34: 1.563 | I34: =G34*H34 -> 58076.454
B35: Rappel 1994 | C35: =139354.43+41278 -> 180632.43 | D35: =C35/K2 -> 27537.236 | H35: 1.563 | I35: =G35*H35 -> 0
B36: Total Germe | D36: =D34+D35 -> 38256.384
B37: INSTITUT SUPERIEUR | C37: 17940 | D37: 2734.94 | E37: 37157.04 | F37: NON | G37: 2734.94 | H37: 1.563 | I37: 4274.7
B38: INSTITUT SUP COMMERCE | C38: 99341 | D38: 15144.44 | E38: 37157.04 | F38: NON | G38: 15144.44 | H38: 1.563 | I38: 23670.76
A39: TOTAL 1995 | H39: =SUM(I34:I38) -> 86021.914
A41: 1996
B42: Rappel 1996 | C42: 23587 | D42: =C42/K2 -> 3595.815 | E42: 37947.46 | F42: NON | G42: 3595.81 | H42: 1.525 | I42: =G42*H42 -> 5483.6102
B43: INSTITUT SUP COMMERCE | C43: 146554 | D43: =C43/K2 -> 22342.013 | E43: 37947.46 | F43: NON | G43: 22342.01 | H43: 1.525 | I43: 34071.57
...

Sheet CNAV CORRIGE
A1: Année/Employeur | B1: Détail | C1: FRF | D1: EUR (avant cap) | E1: Plafond EUR | F1: Dépassement | G1: Sommes retenues | H1: Coef | I1: EUR Actualisé | K1: 1 euro
A2: 1990 | K2: 6.55957
B3: GERME | C3: 33120 | D3: 5049.11 | E3: 19976.92 | F3: NON | G3: 5049.11 | H3: 1.689 | I3: 8527.95
B4: Rappels Germe 1990 | C4: 19791.71 | D4: 3017.23 | E4: =E3 -> 19976.92 | F4: NON | G4: 3017.23 | H4: 1.689 | I4: 5096.1
A5: TOTAL 1990 | B5: Total Germe | C5: =SUM(C3:C4) -> 52911.71 | D5: =SUM(D3:D4) -> 8066.34 | E5: =E4 -> 19976.92 | F5: NON | G5: =G3+G4 -> 8066.34 | H5: 1.689 | I5: =SUM(I3:I4) -> 13624.05
A7: 1991
B8: GERME | C8: 112024 | D8: 17077.95 | E8: 21001.38
B9: Rappels 1991 | C9: 68913 | D9: 10505.72 | E9: =E8 -> 21001.38
A10: TOTAL 1991 | B10: Total Germe | C10: =SUM(C8:C9) -> 180937 | D10: =SUM(D8:D9) -> 27583.67 | E10: =E9 -> 21001.38 | F10: OUI | G10: =E9 -> 21001.38 | H10: 1.663 | I10: =G10*H10 -> 34925.295
A12: 1992
B13: GERME | C13: 103829 | D13: 15828.63 | E13: =21970.95 -> 21970.95
B14: Rappels Germe 1992 | C14: 63512.61 | D14: 9682.43 | E14: =E13 -> 21970.95
B15: Sous total Germe | C15: =C13+C14 -> 167341.61 | D15: =SUM(D13:D14) -> 25511.06 | E15: =E14 -> 21970.95 | F15: OUI | G15: 21970.63 | H15: 1.609 | I15: 4855.03
B16: OBJECTIF FORMATION | C16: 16485 | D16: 2513.12 | E16: =E15 -> 21970.95 | F16: NON | G16: 2513.12 | H16: 1.609 | I16: 4043.61
B17: GROUP EUROP | C17: 5400 | D17: 823.22 | E17: =E16 -> 21970.95 | F17: NON | G17: 823.22 | H17: 1.609 | I17: 1324.57
A18: TOTAL 1992 | B18: Totaux | C18: =SUM(C14:C17) -> 252739.22 | G18: =SUM(G15:G17) -> 25306.97 | H18: 1.609 | I18: =G18*H18 -> 40718.915
A20: 1993
B21: GERME | C21: 99462 | D21: 15162.88
B22: Rappels GERME 1993 | C22: 72191.01 | D22: 11005.45
B23: Sous total Germe | C23: =SUM(D21) -> 15162.88 | D23: =SUM(D21:D22) -> 26168.33 | E23: 22839.91 | F23: OUI | G23: =E23 -> 22839.91 | H23: 1.609 | I23: =G23*H23 -> 36749.415
B24: OBJECTIF FORMATION | C24: 70245 | D24: =C24/K2 -> 10708.781 | E24: 22839.91 | F24: NON | G24: =D24 -> 10708.781 | H24: 1.609 | I24: =G24*H24 -> 17230.429
B25: GROUP EUROP | C25: 9000 | D25: 1372.04 | E25: 22839.91 | F25: NON | G25: 1372.04 | H25: 1.609 | I25: =G25*H25 -> 2207.6124
A26: TOTAL 1993 | B26: Totaux | C26: =C23+C24+C25 -> 94407.88 | D26: =D23+D24+D25 -> 38249.151 | G26: =SUM(G23:G25) -> 34920.731 | H26: 1.609 | I26: =G26*H26 -> 56187.457
A28: 1994
B29: GERME | C29: 139800 | D29: =C29/K2 -> 21312.373
B30: Rappels 1994 | C30: 84581.68 | D30: =C30/K2 -> 12894.394
B31: Sous total Germe | C31: =SUM(C29:C30) -> 224381.68 | D31: =SUM(D29:D30) -> 34206.767 | E31: 23342.99 | F31: OUI | G31: =E31 -> 23342.99 | H31: 1.581 | I31: =G31*H31 -> 36905.267
B32: OBJECTIF FORMATION | C32: 30760 | D32: =C32/K2 -> 4689.3318 | E32: 23342.99 | F32: NON | G32: =D32 -> 4689.3318 | H32: 1.581 | I32: =G32*H32 -> 7413.8335
B33: INSTITUT SUP | C33: 16350 | D33: =C33/K2 -> 2492.5414 | E33: 23342.99 | F33: NON | G33: =D33 -> 2492.5414 | H33: 1.581 | I33: =G33*H33 -> 3940.708
A34: TOTAL 1994 | B34: Totaux | C34: =C31+C32+C33 -> 271491.68 | D34: =D31+D32+D33 -> 41388.64 | G34: =SUM(G31:G33) -> 30524.863 | H34: 1.581 | I34: =SUM(I31:I33) -> 48259.809
C35: =C29+C32+C33 -> 186910
A36: 1995
B37: GERME | C37: 70313 | D37: =C37/K2 -> 10719.148
B38: Germe rappel bulletin arrêt 1997 | C38: 448344.41 | D38: =C38/K2 -> 68349.665
B39: Sous total 1 Germe sur relevé | C39: =SUM(C37:C38) -> 518657.41 | D39: =C39/K2 -> 79068.812
B40: Rappel bulletin1 arrêt 1996 | C40: 41278 | D40: =C40/K2 -> 6292.7905
B41: Sous total 2 Germe | C41: =C39+C40 -> 559935.41 | D41: =D39+D40 -> 85361.603 | E41: 31157.04 | F41: OUI | G41: 31157.04 | H41: 1.563 | I41: =G41*H41 -> 48698.454
B42: Institut sup comm Orsay | C42: 34700 | D42: =C42/K2 -> 5289.9809 | E42: 37157.04 | F42: NON | G42: 2734.94 | H42: 1.563 | I42: =G42*H42 -> 4274.7112
B43: ISIC/ISIFA | C43: 11615 | D43: 15144.44 | E43: 37157.04 | F43: NON | G43: 15144.44 | H43: 1.563 | I43: =G43*H43 -> 23670.76
A44: TOTAL 1995 | B44: Totaux | C44: =C41+C42+C43 -> 606250.41 | G44: =G41+G42+G43 -> 49036.42 | I44: =SUM(I37:I43) -> 76643.924
...

Sheet 25 Meilleures Années
A1: Année | B1: Montant corrigé (€) | D1: 6.55957 | E1: Montant corrigé (€) | G1: Montants CNAV (€)
A2: 1991 | B2: ='CNAV CORRIGE'!I10 -> 34925.295 | D2: 1.677 | E2: =B2*D2 -> 58569.72 | G2: 28639.72 | I2: =G2/D2 -> 17077.949 | J2: =I2*$D$1 -> 112024
A3: 1992 | B3: ='CNAV CORRIGE'!I18 -> 40718.915 | D3: 1.623 | E3: =B3*D3 -> 66086.799 | G3: 36002.04 | I3: =G3/D3 -> 22182.403 | J3: =I3*$D$1 -> 145507.02
A4: 1993 | B4: ='CNAV CORRIGE'!I26 -> 56187.457 | D4: 1.623 | E4: =B4*D4 -> 91192.242 | G4: 44216.54 | I4: =G4/D4 -> 27243.709 | J4: =I4*$D$1 -> 178707.02
A5: 1994 | B5: ='CNAV CORRIGE'!I34 -> 48259.809 | D5: 1.595 | E5: =B5*D5 -> 76974.395 | G5: 47704.38 | I5: =G5/D5 -> 29908.702 | J5: =I5*$D$1 -> 196188.23
A6: 1995 | B6: ='CNAV CORRIGE'!I44 -> 76643.924 | D6: 1.577 | E6: =B6*D6 -> 120867.47 | G6: 140146.81 | I6: =G6/D6 -> 88869.252 | J6: =I6*$D$1 -> 582944.08
A7: 1996 | B7: ='CNAV CORRIGE'!I49 -> 17189.737 | D7: 1.538 | E7: =B7*D7 -> 26437.815 | G7: 27014.51 | I7: =G7/D7 -> 17564.701 | J7: =I7*$D$1 -> 115216.89
A8: 1997 | B8: =45288/D1 -> 6904.1111 | D8: 1.522 | E8: =B8*D8 -> 10508.057 | G8: =E8 -> 10508.057 | I8: =G8/D8 -> 6904.1111 | J8: =I8*$D$1 -> 45288
A9: 1999 | B9: =51987/D1 -> 7925.3671 | D9: 1.487 | E9: =B9*D9 -> 11785.021 | G9: =E9 -> 11785.021 | I9: =G9/D9 -> 7925.3671 | J9: =I9*$D$1 -> 51987
A10: 2002 | B10: 9208 | D10: 1.418 | E10: =B10*D10 -> 13056.944 | G10: =E10 -> 13056.944 | I10: =G10/D10 -> 9208
A11: 2003 | B11: 9031 | D11: 1.395 | E11: =B11*D11 -> 12598.245 | G11: =E11 -> 12598.245 | I11: =G11/D11 -> 9031
A12: 2004 | B12: 18000 | D12: 1.374 | E12: =B12*D12 -> 24732 | G12: =E12 -> 24732 | I12: =G12/D12 -> 18000
A13: 2005 | B13: 18000 | D13: 1.348 | E13: =B13*D13 -> 24264 | G13: =E13 -> 24264 | I13: =G13/D13 -> 18000
A14: 2006 | B14: 22000 | D14: 1.324 | E14: =B14*D14 -> 29128 | G14: =E14 -> 29128 | I14: =G14/D14 -> 22000
A15: 2007 | B15: 17288.52 | D15: 1.302 | E15: =B15*D15 -> 22509.653 | G15: =E15 -> 22509.653 | I15: =G15/D15 -> 17288.52
A16: 2008 | B16: 15057.53 | D16: 1.29 | E16: =B16*D16 -> 19424.214 | G16: =E16 -> 19424.214 | I16: =G16/D16 -> 15057.53
A17: 2010 | B17: 18000 | D17: 1.267 | E17: =B17*D17 -> 22806 | G17: =E17 -> 22806 | I17: =G17/D17 -> 18000
A18: 2011 | B18: 10500 | D18: 1.256 | E18: =B18*D18 -> 13188 | G18: =E18 -> 13188 | I18: =G18/D18 -> 10500
A19: 2012 | B19: 27117.04 | D19: 1.231 | E19: =B19*D19 -> 33381.076 | G19: =E19 -> 33381.076 | I19: =G19/D19 -> 27117.04
A20: 2013 | B20: 33600 | D20: 1.205 | E20: =B20*D20 -> 40488 | G20: 39988.17 | I20: =G20/D20 -> 33185.203
A21: 2014 | B21: 36000 | D21: 1.191 | E21: =B21*D21 -> 42876 | G21: =E21 -> 42876 | I21: =G21/D21 -> 36000
A22: 2015 | B22: 36000 | D22: 1.191 | E22: =B22*D22 -> 42876 | G22: =E22 -> 42876 | I22: =G22/D22 -> 36000
A23: 2016 | B23: 36000 | D23: 1.19 | E23: =B23*D23 -> 42840 | G23: =E23 -> 42840 | I23: =G23/D23 -> 36000
A24: 2017 | B24: 36000 | D24: 1.19 | E24: =B24*D24 -> 42840 | G24: =E24 -> 42840 | I24: =G24/D24 -> 36000
A25: 2018 | B25: 36000 | D25: 1.181 | E25: =B25*D25 -> 42516 | G25: =E25 -> 42516 | I25: =G25/D25 -> 36000
A26: 2025 | B26: 22031 | D26: 1.009 | E26: =B26*D26 -> 22229.279 | G26: =E26 -> 22229.279 | I26: =G26/D26 -> 22031
A28: TOTAL 25 ANS | E28: =SUM(E2:E26) -> 954174.93 | G28: =SUM(G2:G27) -> 837270.66
A29: MOYENNE (÷25) | E29: =E28/25 -> 38166.997 | G29: =G28/25 -> 33490.826
A31: CALCUL RETRAITE
A32: Taux (50%): | D32: 0.5 | E32: =E29*D32 -> 19083.499 | G32: =G29*D32 -> 16745.413
A33: Montant annuel: | E33: =(E32/167)*121 -> 13826.966 | G33: =(G32/167)*121 -> 12132.904
A34: Montant mensuel: | E34: =E33/12 -> 1152.2472 | G34: =G33/12 -> 1011.0753

Sheet CORRIGE+BULLEIN2 DE 1996
A1: CNAV | B1: Détail | C1: FRF | D1: EUR (avant cap) | E1: Plafond EUR | F1: Dépassement | G1: Sommes retenues | H1: Coef | I1: EUR Actualisé | K1: 1 euro
A2: 1990 | K2: 6.55957
B3: GERME | C3: 33120 | D3: 5049.11 | E3: 19976.92 | F3: NON | G3: 5049.11 | H3: 1.689 | I3: 8527.95
B4: Rappels Germe 1990 | C4: 19791.71 | D4: 3017.23 | E4: =E3 -> 19976.92 | F4: NON | G4: 3017.23 | H4: 1.689 | I4: 5096.1
A5: TOTAL 1990 | B5: Total Germe | C5: =SUM(C3:C4) -> 52911.71 | D5: =SUM(D3:D4) -> 8066.34 | E5: =E4 -> 19976.92 | F5: NON | G5: =G3+G4 -> 8066.34 | H5: 1.689 | I5: =SUM(I3:I4) -> 13624.05
A7: 1991
B8: GERME | C8: 112024 | D8: 17077.95 | E8: 21001.38
B9: Rappels 1991 | C9: 68913 | D9: 10505.72 | E9: =E8 -> 21001.38
A10: TOTAL 1991 | B10: Total Germe | C10: =SUM(C8:C9) -> 180937 | D10: =SUM(D8:D9) -> 27583.67 | E10: =E9 -> 21001.38 | F10: OUI | G10: =E9 -> 21001.38 | H10: 1.663 | I10: =G10*H10 -> 34925.295
A12: 1992
B13: GERME | C13: 103829 | D13: 15828.63 | E13: =21970.95 -> 21970.95
B14: Rappels Germe 1992 | C14: 63512.61 | D14: 9682.43 | E14: =E13 -> 21970.95
B15: Sous total Germe | C15: =C13+C14 -> 167341.61 | D15: =SUM(D13:D14) -> 25511.06 | E15: =E14 -> 21970.95 | F15: OUI | G15: 21970.63 | H15: 1.609 | I15: 4855.03
B16: OBJECTIF FORMATION | C16: 16485 | D16: 2513.12 | E16: =E15 -> 21970.95 | F16: NON | G16: 2513.12 | H16: 1.609 | I16: 4043.61
B17: GROUP EUROP | C17: 5400 | D17: 823.22 | E17: =E16 -> 21970.95 | F17: NON | G17: 823.22 | H17: 1.609 | I17: 1324.57
A18: TOTAL 1992 | B18: Totaux | C18: =SUM(C14:C17) -> 252739.22 | G18: =SUM(G15:G17) -> 25306.97 | H18: 1.609 | I18: =G18*H18 -> 40718.915
A20: 1993
B21: GERME | C21: 99462 | D21: 15162.88
B22: Rappels GERME 1993 | C22: 72191.01 | D22: 11005.45
B23: Sous total Germe | C23: =SUM(D21) -> 15162.88 | D23: =SUM(D21:D22) -> 26168.33 | E23: 22839.91 | F23: OUI | G23: =E23 -> 22839.91 | H23: 1.609 | I23: =G23*H23 -> 36749.415
B24: OBJECTIF FORMATION | C24: 70245 | D24: =C24/K2 -> 10708.781 | E24: 22839.91 | F24: NON | G24: =D24 -> 10708.781 | H24: 1.609 | I24: =G24*H24 -> 17230.429
B25: GROUP EUROP | C25: 9000 | D25: 1372.04 | E25: 22839.91 | F25: NON | G25: 1372.04 | H25: 1.609 | I25: =G25*H25 -> 2207.6124
A26: TOTAL 1993 | B26: Totaux | C26: =C23+C24+C25 -> 94407.88 | D26: =D23+D24+D25 -> 38249.151 | G26: =SUM(G23:G25) -> 34920.731 | H26: 1.609 | I26: =G26*H26 -> 56187.457
A28: 1994
B29: GERME | C29: 139800 | D29: =C29/K2 -> 21312.373
B30: Rappels 1994 | C30: 84581.68 | D30: =C30/K2 -> 12894.394
B31: Sous total Germe | C31: =SUM(C29:C30) -> 224381.68 | D31: =SUM(D29:D30) -> 34206.767 | E31: 23342.99 | F31: OUI | G31: =E31 -> 23342.99 | H31: 1.581 | I31: =G31*H31 -> 36905.267
B32: OBJECTIF FORMATION | C32: 30760 | D32: =C32/K2 -> 4689.3318 | E32: 23342.99 | F32: NON | G32: =D32 -> 4689.3318 | H32: 1.581 | I32: =G32*H32 -> 7413.8335
B33: INSTITUT SUP | C33: 16350 | D33: =C33/K2 -> 2492.5414 | E33: 23342.99 | F33: NON | G33: =D33 -> 2492.5414 | H33: 1.581 | I33: =G33*H33 -> 3940.708
A34: TOTAL 1994 | B34: Totaux | C34: =C31+C32+C33 -> 271491.68 | D34: =D31+D32+D33 -> 41388.64 | G34: =SUM(G31:G33) -> 30524.863 | H34: 1.581 | I34: =SUM(I31:I33) -> 48259.809
C35: =C29+C32+C33 -> 186910
A36: 1995
B37: GERME | C37: 70313 | D37: =C37/K2 -> 10719.148
B38: Germe rappel bulletin arrêt 1997 | C38: 448344.41 | D38: =C38/K2 -> 68349.665
B39: Sous total 1 Germe sur relevé | C39: =SUM(C37:C38) -> 518657.41 | D39: =C39/K2 -> 79068.812
B40: Rappel bulletin 1 arrêt 1996 | C40: 41278 | D40: =C40/K2 -> 6292.7905
B41: Sous total 2 Germe | C41: =C39+C40 -> 559935.41 | D41: =D39+D40 -> 85361.603 | E41: 31157.04 | F41: OUI | G41: 31157.04 | H41: 1.563 | I41: =G41*H41 -> 48698.454
B42: Institut sup comm Orsay | C42: 34700 | D42: =C42/K2 -> 5289.9809 | E42: 37157.04 | F42: NON | G42: =D42 -> 5289.9809 | H42: 1.563 | I42: =G42*H42 -> 8268.2401
B43: ISIC/ISIFA | C43: 11615 | D43: =C43/K2 -> 1770.6953 | E43: 37157.04 | F43: NON | G43: =D43 -> 1770.6953 | H43: 1.563 | I43: =G43*H43 -> 2767.5968
A44: TOTAL 1995 | B44: Totaux | C44: =C41+C42+C43 -> 606250.41 | D44: =D41+D42+D43 -> 92422.279 | G44: =G41+G42+G43 -> 38217.716 | H44: 1.563 | I44: =G44*H44 -> 59734.29
...

Sheet 25années avec Bulletin2 de 1996
A1: Année | B1: Montant corrigé (€) | D1: 6.55957 | E1: Montant Valorisé corrigé (€) | G1: Montants CNAV valorisé (€) | I1: Montants CNAV non valorisés
A2: 1991 | B2: ='CNAV CORRIGE'!I10 -> 34925.295 | D2: 1.677 | E2: =B2*D2 -> 58569.72 | G2: 28639.72 | I2: =G2/D2 -> 17077.949 | J2: =I2*$D$1 -> 112024
A3: 1992 | B3: ='CNAV CORRIGE'!I18 -> 40718.915 | D3: 1.623 | E3: =B3*D3 -> 66086.799 | G3: 36002.04 | I3: =G3/D3 -> 22182.403 | J3: =I3*$D$1 -> 145507.02
A4: 1993 | B4: ='CNAV CORRIGE'!I26 -> 56187.457 | D4: 1.623 | E4: =B4*D4 -> 91192.242 | G4: 44216.54 | I4: =G4/D4 -> 27243.709 | J4: =I4*$D$1 -> 178707.02
A5: 1994 | B5: ='CNAV CORRIGE'!I34 -> 48259.809 | D5: 1.595 | E5: =B5*D5 -> 76974.395 | G5: 47704.38 | I5: =G5/D5 -> 29908.702 | J5: =I5*$D$1 -> 196188.23
A6: 1995 | B6: ='CNAV CORRIGE'!I44 -> 76643.924 | D6: 1.577 | E6: =B6*D6 -> 120867.47 | G6: 140146.81 | I6: =G6/D6 -> 88869.252 | J6: =I6*$D$1 -> 582944.08 | K6: 448344.41
A7: 1996 | B7: ='CORRIGE+BULLEIN2 DE 1996'!I51 -> 30168.851 | D7: 1.538 | E7: =B7*D7 -> 46399.692 | G7: 27014.51 | I7: =G7/D7 -> 17564.701 | J7: =I7*$D$1 -> 115216.89 | K7: ='CORRIGE+BULLEIN2 DE 1996'!C37 -> 70313
A8: 1997 | B8: =45288/D1 -> 6904.1111 | D8: 1.522 | E8: =B8*D8 -> 10508.057 | G8: =E8 -> 10508.057 | I8: =G8/D8 -> 6904.1111 | J8: =I8*$D$1 -> 45288 | K8: ='CORRIGE+BULLEIN2 DE 1996'!C42 -> 34700
A9: 1999 | B9: =51987/D1 -> 7925.3671 | D9: 1.487 | E9: =B9*D9 -> 11785.021 | G9: =E9 -> 11785.021 | I9: =G9/D9 -> 7925.3671 | J9: =I9*$D$1 -> 51987 | K9: 19356
A10: 2002 | B10: 9208 | D10: 1.418 | E10: =B10*D10 -> 13056.944 | G10: =E10 -> 13056.944 | I10: =G10/D10 -> 9208 | K10: =SUM(K6:K9) -> 572713.41
A11: 2003 | B11: 9031 | D11: 1.395 | E11: =B11*D11 -> 12598.245 | G11: =E11 -> 12598.245 | I11: =G11/D11 -> 9031 | K11: =J6-K10 -> 10230.668
A12: 2004 | B12: 18000 | D12: 1.374 | E12: =B12*D12 -> 24732 | G12: =E12 -> 24732 | I12: =G12/D12 -> 18000
A13: 2005 | B13: 18000 | D13: 1.348 | E13: =B13*D13 -> 24264 | G13: =E13 -> 24264 | I13: =G13/D13 -> 18000
A14: 2006 | B14: 22000 | D14: 1.324 | E14: =B14*D14 -> 29128 | G14: =E14 -> 29128 | I14: =G14/D14 -> 22000
A15: 2007 | B15: 17288.52 | D15: 1.302 | E15: =B15*D15 -> 22509.653 | G15: =E15 -> 22509.653 | I15: =G15/D15 -> 17288.52
A16: 2008 | B16: 15057.53 | D16: 1.29 | E16: =B16*D16 -> 19424.214 | G16: =E16 -> 19424.214 | I16: =G16/D16 -> 15057.53
A17: 2010 | B17: 18000 | D17: 1.267 | E17: =B17*D17 -> 22806 | G17: =E17 -> 22806 | I17: =G17/D17 -> 18000
A18: 2011 | B18: 10500 | D18: 1.256 | E18: =B18*D18 -> 13188 | G18: =E18 -> 13188 | I18: =G18/D18 -> 10500
A19: 2012 | B19: 27117.04 | D19: 1.231 | E19: =B19*D19 -> 33381.076 | G19: =E19 -> 33381.076 | I19: =G19/D19 -> 27117.04
A20: 2013 | B20: 33600 | D20: 1.205 | E20: =B20*D20 -> 40488 | G20: 39988.17 | I20: =G20/D20 -> 33185.203
A21: 2014 | B21: 36000 | D21: 1.191 | E21: =B21*D21 -> 42876 | G21: =E21 -> 42876 | I21: =G21/D21 -> 36000
A22: 2015 | B22: 36000 | D22: 1.191 | E22: =B22*D22 -> 42876 | G22: =E22 -> 42876 | I22: =G22/D22 -> 36000
A23: 2016 | B23: 36000 | D23: 1.19 | E23: =B23*D23 -> 42840 | G23: =E23 -> 42840 | I23: =G23/D23 -> 36000
A24: 2017 | B24: 36000 | D24: 1.19 | E24: =B24*D24 -> 42840 | G24: =E24 -> 42840 | I24: =G24/D24 -> 36000
A25: 2018 | B25: 36000 | D25: 1.181 | E25: =B25*D25 -> 42516 | G25: =E25 -> 42516 | I25: =G25/D25 -> 36000
A26: 2025 | B26: 22031 | D26: 1.009 | E26: =B26*D26 -> 22229.279 | G26: =E26 -> 22229.279 | I26: =G26/D26 -> 22031
A28: TOTAL 25 ANS | E28: =SUM(E2:E26) -> 974136.81 | G28: =SUM(G2:G27) -> 837270.66
A29: MOYENNE (÷25) | E29: =E28/25 -> 38965.472 | G29: =G28/25 -> 33490.826
A31: CALCUL RETRAITE
A32: Taux (50%): | D32: 0.5 | E32: =E29*D32 -> 19482.736 | G32: =G29*D32 -> 16745.413
A33: Montant annuel: | E33: =(E32/167)*121 -> 14116.234 | G33: =(G32/167)*121 -> 12132.904
A34: Montant mensuel: | E34: =E33/12 -> 1176.3528 | G34: =G33/12 -> 1011.0753

Sheet CNAV CORR SANS PLAFOND 1 BULL96
A1: CNAV | B1: Détail | C1: FRF | D1: EUR (avant cap) | E1: Coef | F1: EUR Actualisé | H1: 1 euro
A2: 1990 | H2: 6.55957
B3: GERME | C3: 33120 | D3: 5049.11 | E3: 1.689 | F3: =D3*E3 -> 8527.9468
B4: Rappels Germe 1990 | C4: 19791.71 | D4: 3017.23 | E4: 1.689 | F4: =D4*E4 -> 5096.1015
A5: TOTAL 1990 | B5: Total Germe | C5: =SUM(C3:C4) -> 52911.71 | D5: =SUM(D3:D4) -> 8066.34 | E5: 1.689 | F5: =D5*E5 -> 13624.048
A7: 1991
B8: GERME | C8: 112024 | D8: =C8/H2 -> 17077.949
B9: Rappels 1991 | C9: 68913 | D9: =C9/H2 -> 10505.719
A10: TOTAL 1991 | B10: Total Germe | C10: =SUM(C8:C9) -> 180937 | D10: =SUM(D8:D9) -> 27583.668 | E10: 1.663 | F10: =D10*E10 -> 45871.64
A12: 1992
B13: GERME | C13: 103829 | D13: =C13/H2 -> 15828.629
B14: Rappels Germe 1992 | C14: 63512.61 | D14: =C14/H2 -> 9682.435
B15: Sous total Germe | C15: =C13+C14 -> 167341.61 | D15: =SUM(D13:D14) -> 25511.064 | E15: 1.609 | F15: =D15*E15 -> 41047.302
B16: OBJECTIF FORMATION | C16: 16485 | D16: =C16/H2 -> 2513.122 | E16: 1.609 | F16: =D16*E16 -> 4043.6134
B17: GROUP EUROP | C17: 5400 | D17: =C17/H2 -> 823.22469 | E17: 1.609 | F17: =D17*E17 -> 1324.5685
A18: TOTAL 1992 | B18: Totaux | C18: =C15+C16+C17 -> 189226.61 | D18: =SUM(D15:D17) -> 28847.411 | E18: 1.609 | F18: =D18*E18 -> 46415.484
A20: 1993
B21: GERME | C21: 99462 | D21: =C21/H2 -> 15162.884
B22: Rappels GERME 1993 | C22: 72191.01 | D22: =C22/H2 -> 11005.449
B23: Sous total Germe | C23: =SUM(C21:C22) -> 171653.01 | D23: =SUM(D21:D22) -> 26168.333 | E23: 1.609 | F23: =D23*E23 -> 42104.847
B24: OBJECTIF FORMATION | C24: 70245 | D24: =C24/H2 -> 10708.781 | E24: 1.609 | F24: =D24*E24 -> 17230.429
B25: GROUP EUROP | C25: 9000 | D25: =C25/H2 -> 1372.0412 | E25: 1.609 | F25: =D25*E25 -> 2207.6142
A26: TOTAL 1993 | B26: Totaux | C26: =C23+C24+C25 -> 250898.01 | D26: =D23+D24+D25 -> 38249.155 | E26: 1.609 | F26: =D26*E26 -> 61542.89
A28: 1994
B29: GERME | C29: 139800 | D29: =C29/H2 -> 21312.373
B30: Rappels 1994 | C30: 84581.68 | D30: =C30/H2 -> 12894.394
B31: Sous total Germe | C31: =SUM(C29:C30) -> 224381.68 | D31: =SUM(D29:D30) -> 34206.767 | E31: 1.581 | F31: =D31*E31 -> 54080.898
B32: OBJECTIF FORMATION | C32: 30760 | D32: =C32/H2 -> 4689.3318 | E32: 1.581 | F32: =D32*E32 -> 7413.8335
B33: INSTITUT SUP | C33: 16350 | D33: =C33/H2 -> 2492.5414 | E33: 1.581 | F33: =D33*E33 -> 3940.708
A34: TOTAL 1994 | B34: Totaux | C34: =C31+C32+C33 -> 271491.68 | D34: =D31+D32+D33 -> 41388.64 | E34: 1.581 | F34: =D34*E34 -> 65435.44
A36: 1995
B37: GERME | C37: 70313 | D37: =C37/H2 -> 10719.148
B38: Germe rappel bulletin arrêt 1997 | C38: 448344.41 | D38: =C38/H2 -> 68349.665
B39: Sous total 1 Germe sur relevé | C39: =SUM(C37:C38) -> 518657.41 | D39: =C39/H2 -> 79068.812
B40: Rappel bulletin 1 arrêt 1996 | C40: 41278 | D40: =C40/H2 -> 6292.7905
B41: Sous total 2 Germe | C41: =C39+C40 -> 559935.41 | D41: =D39+D40 -> 85361.603 | E41: 1.563 | F41: =D41*E41 -> 133420.19
B42: Institut sup comm Orsay | C42: 34700 | D42: =C42/H2 -> 5289.9809 | E42: 1.563 | F42: =D42*E42 -> 8268.2401
B43: ISIC/ISIFA | C43: 11615 | D43: =C43/H2 -> 1770.6953 | E43: 1.563 | F43: =D43*E43 -> 2767.5968
A44: TOTAL 1995 | B44: Totaux | C44: =C41+C42+C43 -> 606250.41 | D44: =D41+D42+D43 -> 92422.279 | E44: 1.563 | F44: =D44*E44 -> 144456.02
A46: 1996
...

Sheet 25 ANNEEES SANS PALF 1 BULL 96
A1: Année | B1: Montant corrigé (€) | D1: 6.55957 | E1: Montant Valorisé corrigé (€) | G1: Montants CNAV valorisé (€) | I1: Montants CNAV non valorisés
A2: 1991 | B2: ='CNAV CORR SANS PLAFOND 1 BULL96'!F10 -> 45871.64 | D2: 1.677 | E2: =B2*D2 -> 76926.74 | G2: 28639.72 | I2: =G2/D2 -> 17077.949 | J2: =I2*$D$1 -> 112024
A3: 1992 | B3: ='CNAV CORR SANS PLAFOND 1 BULL96'!F18 -> 46415.484 | D3: 1.623 | E3: =B3*D3 -> 75332.33 | G3: 36002.04 | I3: =G3/D3 -> 22182.403 | J3: =I3*$D$1 -> 145507.02
A4: 1993 | B4: ='CNAV CORR SANS PLAFOND 1 BULL96'!F26 -> 61542.89 | D4: 1.623 | E4: =B4*D4 -> 99884.111 | G4: 44216.54 | I4: =G4/D4 -> 27243.709 | J4: =I4*$D$1 -> 178707.02
A5: 1994 | B5: ='CNAV CORR SANS PLAFOND 1 BULL96'!F34 -> 65435.44 | D5: 1.595 | E5: =B5*D5 -> 104369.53 | G5: 47704.38 | I5: =G5/D5 -> 29908.702 | J5: =I5*$D$1 -> 196188.23
A6: 1995 | B6: ='CNAV CORR SANS PLAFOND 1 BULL96'!F44 -> 144456.02 | D6: 1.577 | E6: =B6*D6 -> 227807.15 | G6: 140146.81 | I6: =G6/D6 -> 88869.252 | J6: =I6*$D$1 -> 582944.08 | K6: 448344.41
A7: 1996 | B7: ='CNAV CORR SANS PLAFOND 1 BULL96'!F49 -> 17189.737 | D7: 1.538 | E7: =B7*D7 -> 26437.815 | G7: 27014.51 | I7: =G7/D7 -> 17564.701 | J7: =I7*$D$1 -> 115216.89 | K7: ='CORRIGE+BULLEIN2 DE 1996'!C37 -> 70313
A8: 1997 | B8: =45288/D1 -> 6904.1111 | D8: 1.522 | E8: =B8*D8 -> 10508.057 | G8: =E8 -> 10508.057 | I8: =G8/D8 -> 6904.1111 | J8: =I8*$D$1 -> 45288 | K8: ='CORRIGE+BULLEIN2 DE 1996'!C42 -> 34700
A9: 1999 | B9: =51987/D1 -> 7925.3671 | D9: 1.487 | E9: =B9*D9 -> 11785.021 | G9: =E9 -> 11785.021 | I9: =G9/D9 -> 7925.3671 | J9: =I9*$D$1 -> 51987 | K9: 19356
A10: 2002 | B10: 9208 | D10: 1.418 | E10: =B10*D10 -> 13056.944 | G10: =E10 -> 13056.944 | I10: =G10/D10 -> 9208 | K10: =SUM(K6:K9) -> 572713.41
A11: 2003 | B11: 9031 | D11: 1.395 | E11: =B11*D11 -> 12598.245 | G11: =E11 -> 12598.245 | I11: =G11/D11 -> 9031 | K11: =J6-K10 -> 10230.668
A12: 2004 | B12: 18000 | D12: 1.374 | E12: =B12*D12 -> 24732 | G12: =E12 -> 24732 | I12: =G12/D12 -> 18000
A13: 2005 | B13: 18000 | D13: 1.348 | E13: =B13*D13 -> 24264 | G13: =E13 -> 24264 | I13: =G13/D13 -> 18000
A14: 2006 | B14: 22000 | D14: 1.324 | E14: =B14*D14 -> 29128 | G14: =E14 -> 29128 | I14: =G14/D14 -> 22000
A15: 2007 | B15: 17288.52 | D15: 1.302 | E15: =B15*D15 -> 22509.653 | G15: =E15 -> 22509.653 | I15: =G15/D15 -> 17288.52
A16: 2008 | B16: 15057.53 | D16: 1.29 | E16: =B16*D16 -> 19424.214 | G16: =E16 -> 19424.214 | I16: =G16/D16 -> 15057.53
A17: 2010 | B17: 18000 | D17: 1.267 | E17: =B17*D17 -> 22806 | G17: =E17 -> 22806 | I17: =G17/D17 -> 18000
A18: 2011 | B18: 10500 | D18: 1.256 | E18: =B18*D18 -> 13188 | G18: =E18 -> 13188 | I18: =G18/D18 -> 10500
A19: 2012 | B19: 27117.04 | D19: 1.231 | E19: =B19*D19 -> 33381.076 | G19: =E19 -> 33381.076 | I19: =G19/D19 -> 27117.04
A20: 2013 | B20: 33600 | D20: 1.205 | E20: =B20*D20 -> 40488 | G20: 39988.17 | I20: =G20/D20 -> 33185.203
A21: 2014 | B21: 36000 | D21: 1.191 | E21: =B21*D21 -> 42876 | G21: =E21 -> 42876 | I21: =G21/D21 -> 36000
A22: 2015 | B22: 36000 | D22: 1.191 | E22: =B22*D22 -> 42876 | G22: =E22 -> 42876 | I22: =G22/D22 -> 36000
A23: 2016 | B23: 36000 | D23: 1.19 | E23: =B23*D23 -> 42840 | G23: =E23 -> 42840 | I23: =G23/D23 -> 36000
A24: 2017 | B24: 36000 | D24: 1.19 | E24: =B24*D24 -> 42840 | G24: =E24 -> 42840 | I24: =G24/D24 -> 36000
A25: 2018 | B25: 36000 | D25: 1.181 | E25: =B25*D25 -> 42516 | G25: =E25 -> 42516 | I25: =G25/D25 -> 36000
A26: 2025 | B26: 22031 | D26: 1.009 | E26: =B26*D26 -> 22229.279 | G26: =E26 -> 22229.279 | I26: =G26/D26 -> 22031
A28: TOTAL 25 ANS | E28: =SUM(E2:E26) -> 1124804.2 | G28: =SUM(G2:G27) -> 837270.66
A29: MOYENNE (÷25) | E29: =E28/25 -> 44992.166 | G29: =G28/25 -> 33490.826
A31: CALCUL RETRAITE
A32: Taux (50%): | D32: 0.5 | E32: =E29*D32 -> 22496.083 | G32: =G29*D32 -> 16745.413
A33: Montant annuel: | E33: =(E32/167)*121 -> 16299.557 | G33: =(G32/167)*121 -> 12132.904
A34: Montant mensuel: | E34: =E33/12 -> 1358.2964 | G34: =G33/12 -> 1011.0753

Sheet CNA CORR SAN PLAFOND 2 BULL 96
A1: CNAV | B1: Détail | C1: FRF | D1: EUR (avant cap) | E1: Coef | F1: EUR Actualisé | H1: 1 euro
A2: 1990 | H2: 6.55957
B3: GERME Salaire de 1990 | C3: 33120 | D3: 5049.11 | E3: 1.689 | F3: =D3*E3 -> 8527.9468
B4: Rappels Germe 1990 | C4: 19791.71 | D4: 3017.23 | E4: 1.689 | F4: =D4*E4 -> 5096.1015
A5: TOTAL 1990 | B5: Total Germe | C5: =SUM(C3:C4) -> 52911.71 | D5: =SUM(D3:D4) -> 8066.34 | E5: 1.689 | F5: =D5*E5 -> 13624.048
A7: 1991
B8: GERME Salaire de 1991 | C8: 112024 | D8: 17077.95
B9: Rappels Germe 1991 | C9: 68913 | D9: 10505.72
A10: TOTAL 1991 | B10: Total Germe | C10: =SUM(C8:C9) -> 180937 | D10: =SUM(D8:D9) -> 27583.67 | E10: 1.663 | F10: =D10*E10 -> 45871.643
A12: 1992
B13: GERME Salaire de 1992 | C13: 103829 | D13: =C13/H2 -> 15828.629
B14: Rappels Germe 1992 | C14: 63512.61 | D14: =C14/H2 -> 9682.435
B15: Sous total Germe | C15: =C13+C14 -> 167341.61 | D15: =SUM(D13:D14) -> 25511.064 | E15: 1.609 | F15: =D15*E15 -> 41047.302
B16: OBJECTIF FORMATION | C16: 16485 | D16: =C16/H2 -> 2513.122 | E16: 1.609 | F16: =D16*E16 -> 4043.6134
B17: GROUP EUROP | C17: 5400 | D17: =C17/H2 -> 823.22469 | E17: 1.609 | F17: =D17*E17 -> 1324.5685
A18: TOTAL 1992 | B18: Totaux | C18: =C15+C16+C17 -> 189226.61 | D18: =SUM(D15:D17) -> 28847.411 | E18: 1.609 | F18: =D18*E18 -> 46415.484
A20: 1993
B21: GERME Salaire de 1993 | C21: 99462 | D21: =C21/H2 -> 15162.884
B22: Rappels GERME 1993 | C22: 72191.01 | D22: =C22/H2 -> 11005.449
B23: Sous total Germe | C23: =SUM(C21:C22) -> 171653.01 | D23: =SUM(D21:D22) -> 26168.333 | E23: 1.609 | F23: =D23*E23 -> 42104.847
B24: OBJECTIF FORMATION | C24: 70245 | D24: =C24/H2 -> 10708.781 | E24: 1.609 | F24: =D24*E24 -> 17230.429
B25: GROUP EUROP | C25: 9000 | D25: =C25/H2 -> 1372.0412 | E25: 1.609 | F25: =D25*E25 -> 2207.6142
A26: TOTAL 1993 | B26: Totaux | C26: =C23+C24+C25 -> 250898.01 | D26: =D23+D24+D25 -> 38249.155 | E26: 1.609 | F26: =D26*E26 -> 61542.89
A28: 1994
B29: GERME Salaire de 1994 | C29: 139800 | D29: =C29/H2 -> 21312.373
B30: Rappels Germe 1994 | C30: 84581.68 | D30: =C30/H2 -> 12894.394
B31: Sous total Germe | C31: =SUM(C29:C30) -> 224381.68 | D31: =SUM(D29:D30) -> 34206.767 | E31: 1.581 | F31: =D31*E31 -> 54080.898
B32: OBJECTIF FORMATION | C32: 30760 | D32: =C32/H2 -> 4689.3318 | E32: 1.581 | F32: =D32*E32 -> 7413.8335
B33: INSTITUT SUP | C33: 16350 | D33: =C33/H2 -> 2492.5414 | E33: 1.581 | F33: =D33*E33 -> 3940.708
A34: TOTAL 1994 | B34: Totaux | C34: =C31+C32+C33 -> 271491.68 | D34: =D31+D32+D33 -> 41388.64 | E34: 1.581 | F34: =D34*E34 -> 65435.44
A36: 1995
B37: GERME Salaire de 1995 | C37: 70313 | D37: =C37/H2 -> 10719.148
B38: Germe rappel bulletin arrêt 1997 | C38: 180630.23 | D38: =C38/H2 -> 27536.901
B39: Sous total 1 Germe sur relevé | C39: =SUM(C37:C38) -> 250943.23 | D39: =C39/H2 -> 38256.049
B40: Rappel bulletin 1 arrêt 1996 | C40: 41278 | D40: =C40/H2 -> 6292.7905
B41: Sous total 2 Germe | C41: =C39+C40 -> 292221.23 | D41: =D39+D40 -> 44548.839 | E41: 1.563 | F41: =D41*E41 -> 69629.836
B42: Institut sup comm Orsay | C42: 34700 | D42: =C42/H2 -> 5289.9809 | E42: 1.563 | F42: =D42*E42 -> 8268.2401
B43: ISIC/ISIFA | C43: 11615 | D43: =C43/H2 -> 1770.6953 | E43: 1.563 | F43: =D43*E43 -> 2767.5968
A44: TOTAL 1995 | B44: Totaux | C44: =C41+C42+C43 -> 338536.23 | D44: =D41+D42+D43 -> 51609.516 | E44: 1.563 | F44: =D44*E44 -> 80665.673
A46: 1996
...

Sheet 25 ANN SAN PLAF 2 BULL 96
A1: Année | B1: Montant corrigé (€) | D1: 6.55957 | E1: Montant Valorisé corrigé (€) | G1: Montants CNAV valorisé (€) | I1: Montants CNAV non valorisés
A2: 1991 | B2: ='CNAV CORR SANS PLAFOND 1 BULL96'!F10 -> 45871.64 | D2: 1.677 | E2: =B2*D2 -> 76926.74 | G2: 28639.72 | I2: =G2/D2 -> 17077.949 | J2: =I2*$D$1 -> 112024
A3: 1992 | B3: ='CNAV CORR SANS PLAFOND 1 BULL96'!F18 -> 46415.484 | D3: 1.623 | E3: =B3*D3 -> 75332.33 | G3: 36002.04 | I3: =G3/D3 -> 22182.403 | J3: =I3*$D$1 -> 145507.02
A4: 1993 | B4: ='CNAV CORR SANS PLAFOND 1 BULL96'!F26 -> 61542.89 | D4: 1.623 | E4: =B4*D4 -> 99884.111 | G4: 44216.54 | I4: =G4/D4 -> 27243.709 | J4: =I4*$D$1 -> 178707.02
A5: 1994 | B5: ='CNAV CORR SANS PLAFOND 1 BULL96'!F34 -> 65435.44 | D5: 1.595 | E5: =B5*D5 -> 104369.53 | G5: 47704.38 | I5: =G5/D5 -> 29908.702 | J5: =I5*$D$1 -> 196188.23
A6: 1995 | B6: ='CNA CORR SAN PLAFOND 2 BULL 96'!F44 -> 80665.673 | D6: 1.577 | E6: =B6*D6 -> 127209.77 | G6: 140146.81 | I6: =G6/D6 -> 88869.252 | J6: =I6*$D$1 -> 582944.08 | K6: 448344.41
A7: 1996 | B7: ='CNA CORR SAN PLAFOND 2 BULL 96'!F51 -> 30168.849 | D7: 1.538 | E7: =B7*D7 -> 46399.689 | G7: 27014.51 | I7: =G7/D7 -> 17564.701 | J7: =I7*$D$1 -> 115216.89 | K7: ='CORRIGE+BULLEIN2 DE 1996'!C37 -> 70313
A8: 1997 | B8: =45288/D1 -> 6904.1111 | D8: 1.522 | E8: =B8*D8 -> 10508.057 | G8: =E8 -> 10508.057 | I8: =G8/D8 -> 6904.1111 | J8: =I8*$D$1 -> 45288 | K8: ='CORRIGE+BULLEIN2 DE 1996'!C42 -> 34700
A9: 1999 | B9: =51987/D1 -> 7925.3671 | D9: 1.487 | E9: =B9*D9 -> 11785.021 | G9: =E9 -> 11785.021 | I9: =G9/D9 -> 7925.3671 | J9: =I9*$D$1 -> 51987 | K9: 19356
A10: 2002 | B10: 9208 | D10: 1.418 | E10: =B10*D10 -> 13056.944 | G10: =E10 -> 13056.944 | I10: =G10/D10 -> 9208 | K10: =SUM(K6:K9) -> 572713.41
A11: 2003 | B11: 9031 | D11: 1.395 | E11: =B11*D11 -> 12598.245 | G11: =E11 -> 12598.245 | I11: =G11/D11 -> 9031 | K11: =J6-K10 -> 10230.668
A12: 2004 | B12: 18000 | D12: 1.374 | E12: =B12*D12 -> 24732 | G12: =E12 -> 24732 | I12: =G12/D12 -> 18000
A13: 2005 | B13: 18000 | D13: 1.348 | E13: =B13*D13 -> 24264 | G13: =E13 -> 24264 | I13: =G13/D13 -> 18000
A14: 2006 | B14: 22000 | D14: 1.324 | E14: =B14*D14 -> 29128 | G14: =E14 -> 29128 | I14: =G14/D14 -> 22000
A15: 2007 | B15: 17288.52 | D15: 1.302 | E15: =B15*D15 -> 22509.653 | G15: =E15 -> 22509.653 | I15: =G15/D15 -> 17288.52
A16: 2008 | B16: 15057.53 | D16: 1.29 | E16: =B16*D16 -> 19424.214 | G16: =E16 -> 19424.214 | I16: =G16/D16 -> 15057.53
A17: 2010 | B17: 18000 | D17: 1.267 | E17: =B17*D17 -> 22806 | G17: =E17 -> 22806 | I17: =G17/D17 -> 18000
A18: 2011 | B18: 10500 | D18: 1.256 | E18: =B18*D18 -> 13188 | G18: =E18 -> 13188 | I18: =G18/D18 -> 10500
A19: 2012 | B19: 27117.04 | D19: 1.231 | E19: =B19*D19 -> 33381.076 | G19: =E19 -> 33381.076 | I19: =G19/D19 -> 27117.04
A20: 2013 | B20: 33600 | D20: 1.205 | E20: =B20*D20 -> 40488 | G20: 39988.17 | I20: =G20/D20 -> 33185.203
A21: 2014 | B21: 36000 | D21: 1.191 | E21: =B21*D21 -> 42876 | G21: =E21 -> 42876 | I21: =G21/D21 -> 36000
A22: 2015 | B22: 36000 | D22: 1.191 | E22: =B22*D22 -> 42876 | G22: =E22 -> 42876 | I22: =G22/D22 -> 36000
A23: 2016 | B23: 36000 | D23: 1.19 | E23: =B23*D23 -> 42840 | G23: =E23 -> 42840 | I23: =G23/D23 -> 36000
A24: 2017 | B24: 36000 | D24: 1.19 | E24: =B24*D24 -> 42840 | G24: =E24 -> 42840 | I24: =G24/D24 -> 36000
A25: 2018 | B25: 36000 | D25: 1.181 | E25: =B25*D25 -> 42516 | G25: =E25 -> 42516 | I25: =G25/D25 -> 36000
A26: 2025 | B26: 22031 | D26: 1.009 | E26: =B26*D26 -> 22229.279 | G26: =E26 -> 22229.279 | I26: =G26/D26 -> 22031
A28: TOTAL 25 ANS | E28: =SUM(E2:E26) -> 1044168.7 | G28: =SUM(G2:G27) -> 837270.66
A29: MOYENNE (÷25) | E29: =E28/25 -> 41766.746 | G29: =G28/25 -> 33490.826
A31: CALCUL RETRAITE
A32: Taux (50%): | D32: 0.5 | E32: =E29*D32 -> 20883.373 | G32: =G29*D32 -> 16745.413
A33: Montant annuel: | E33: =(E32/167)*121 -> 15131.067 | G33: =(G32/167)*121 -> 12132.904
A34: Montant mensuel: | E34: =E33/12 -> 1260.9222 | G34: =G33/12 -> 1011.0753

Sheet Feuil7
